2016-10-14 16:47:38,614 INFO: finance hub startup [in /home/ubuntu/workspace/finance/app/__init__.py:49]
2016-10-14 16:49:07,822 INFO: finance hub startup [in /home/ubuntu/workspace/finance/app/__init__.py:49]
2016-10-14 16:49:11,568 INFO: Successfully connected to finance [in db_utils.py:15]
2016-10-14 19:13:59,546 INFO: finance hub startup [in /home/ubuntu/workspace/finance/app/__init__.py:49]
2016-10-14 19:14:01,363 INFO: Successfully connected to finance [in db_utils.py:22]
2016-10-14 19:15:25,821 INFO: finance hub startup [in /home/ubuntu/workspace/finance/app/__init__.py:49]
2016-10-14 19:15:26,731 INFO: Successfully connected to finance [in db_utils.py:22]
2016-10-14 19:15:26,731 INFO: DB SELECT ERROR:(1146, "Table 'finance.finance' doesn't exist") [in db_utils.py:37]
2016-10-14 19:16:05,703 INFO: finance hub startup [in /home/ubuntu/workspace/finance/app/__init__.py:49]
2016-10-14 19:16:06,596 INFO: Successfully connected to finance [in db_utils.py:22]
2016-10-14 19:16:06,597 INFO: DB SELECT ERROR:(1146, "Table 'finance.finance' doesn't exist") [in db_utils.py:38]
2016-10-14 19:16:19,630 INFO: finance hub startup [in /home/ubuntu/workspace/finance/app/__init__.py:49]
2016-10-14 19:16:20,640 INFO: Successfully connected to finance [in db_utils.py:22]
2016-10-14 19:16:20,641 INFO: DB SELECT ERROR:name 'exce_string' is not defined [in db_utils.py:38]
2016-10-14 19:16:39,156 INFO: finance hub startup [in /home/ubuntu/workspace/finance/app/__init__.py:49]
2016-10-14 19:16:40,061 INFO: Successfully connected to finance [in db_utils.py:22]
2016-10-14 19:16:51,012 INFO: finance hub startup [in /home/ubuntu/workspace/finance/app/__init__.py:49]
2016-10-14 19:16:52,203 INFO: Successfully connected to finance [in db_utils.py:22]
2016-10-14 19:16:52,204 INFO: DB SELECT ERROR:(1146, "Table 'finance.finance' doesn't exist") [in db_utils.py:38]
2016-10-14 19:17:12,213 INFO: finance hub startup [in /home/ubuntu/workspace/finance/app/__init__.py:49]
2016-10-14 19:17:13,188 INFO: Successfully connected to finance [in db_utils.py:22]
2016-10-14 19:17:13,189 INFO: DB SELECT ERROR:(1146, "Table 'finance.finance' doesn't exist") [in db_utils.py:38]
2016-10-14 19:17:33,193 INFO: finance hub startup [in /home/ubuntu/workspace/finance/app/__init__.py:49]
2016-10-14 19:17:34,042 INFO: Successfully connected to finance [in db_utils.py:22]
2016-10-14 19:19:18,724 INFO: finance hub startup [in /home/ubuntu/workspace/finance/app/__init__.py:49]
2016-10-14 19:19:19,445 INFO: Successfully connected to finance [in db_utils.py:22]
2016-10-17 01:10:15,118 INFO: finance hub startup [in /home/ubuntu/workspace/finance/app/__init__.py:49]
2016-10-17 01:23:11,915 INFO: finance hub startup [in /home/ubuntu/workspace/finance/app/__init__.py:49]
2016-10-17 01:23:25,969 INFO: finance hub startup [in /home/ubuntu/workspace/finance/app/__init__.py:49]
2016-10-17 01:23:33,518 ERROR: Exception on /favicon.ico [GET] [in /home/ubuntu/miniconda3/lib/python3.5/site-packages/flask/app.py:1587]
Traceback (most recent call last):
  File "/home/ubuntu/miniconda3/lib/python3.5/site-packages/flask/app.py", line 1639, in full_dispatch_request
    rv = self.dispatch_request()
  File "/home/ubuntu/miniconda3/lib/python3.5/site-packages/flask/app.py", line 1617, in dispatch_request
    self.raise_routing_exception(req)
  File "/home/ubuntu/miniconda3/lib/python3.5/site-packages/flask/app.py", line 1600, in raise_routing_exception
    raise request.routing_exception
  File "/home/ubuntu/miniconda3/lib/python3.5/site-packages/flask/ctx.py", line 294, in match_request
    self.url_adapter.match(return_rule=True)
  File "/home/ubuntu/miniconda3/lib/python3.5/site-packages/werkzeug/routing.py", line 1563, in match
    raise NotFound()
werkzeug.exceptions.NotFound: 404: Not Found

During handling of the above exception, another exception occurred:

Traceback (most recent call last):
  File "/home/ubuntu/miniconda3/lib/python3.5/site-packages/flask/app.py", line 1988, in wsgi_app
    response = self.full_dispatch_request()
  File "/home/ubuntu/miniconda3/lib/python3.5/site-packages/flask/app.py", line 1641, in full_dispatch_request
    rv = self.handle_user_exception(e)
  File "/home/ubuntu/miniconda3/lib/python3.5/site-packages/flask/app.py", line 1539, in handle_user_exception
    return self.handle_http_exception(e)
  File "/home/ubuntu/miniconda3/lib/python3.5/site-packages/flask/app.py", line 1498, in handle_http_exception
    return handler(e)
  File "/home/ubuntu/workspace/finance/app/views.py", line 40, in not_found_error
    return render_template('404.html'), 404
  File "/home/ubuntu/miniconda3/lib/python3.5/site-packages/flask/templating.py", line 134, in render_template
    context, ctx.app)
  File "/home/ubuntu/miniconda3/lib/python3.5/site-packages/flask/templating.py", line 116, in _render
    rv = template.render(context)
  File "/home/ubuntu/miniconda3/lib/python3.5/site-packages/jinja2/environment.py", line 989, in render
    return self.environment.handle_exception(exc_info, True)
  File "/home/ubuntu/miniconda3/lib/python3.5/site-packages/jinja2/environment.py", line 754, in handle_exception
    reraise(exc_type, exc_value, tb)
  File "/home/ubuntu/miniconda3/lib/python3.5/site-packages/jinja2/_compat.py", line 37, in reraise
    raise value.with_traceback(tb)
  File "/home/ubuntu/workspace/finance/app/templates/404.html", line 2, in top-level template code
    {% extends "base.html" %}
  File "/home/ubuntu/workspace/finance/app/templates/base.html", line 34, in top-level template code
    {% block content %}{% endblock %}
  File "/home/ubuntu/workspace/finance/app/templates/404.html", line 6, in block "content"
    <p><a href="{{ url_for('') }}">Back</a></p>
  File "/home/ubuntu/miniconda3/lib/python3.5/site-packages/flask/helpers.py", line 332, in url_for
    return appctx.app.handle_url_build_error(error, endpoint, values)
  File "/home/ubuntu/miniconda3/lib/python3.5/site-packages/flask/app.py", line 1811, in handle_url_build_error
    reraise(exc_type, exc_value, tb)
  File "/home/ubuntu/miniconda3/lib/python3.5/site-packages/flask/_compat.py", line 33, in reraise
    raise value
  File "/home/ubuntu/miniconda3/lib/python3.5/site-packages/flask/helpers.py", line 322, in url_for
    force_external=external)
  File "/home/ubuntu/miniconda3/lib/python3.5/site-packages/werkzeug/routing.py", line 1758, in build
    raise BuildError(endpoint, values, method, self)
werkzeug.routing.BuildError: Could not build url for endpoint ''. Did you mean 'equity_screener' instead?
2016-10-17 01:24:37,947 INFO: finance hub startup [in /home/ubuntu/workspace/finance/app/__init__.py:49]
2016-10-17 01:24:42,232 ERROR: Exception on /favicon.ico [GET] [in /home/ubuntu/miniconda3/lib/python3.5/site-packages/flask/app.py:1587]
Traceback (most recent call last):
  File "/home/ubuntu/miniconda3/lib/python3.5/site-packages/flask/app.py", line 1639, in full_dispatch_request
    rv = self.dispatch_request()
  File "/home/ubuntu/miniconda3/lib/python3.5/site-packages/flask/app.py", line 1617, in dispatch_request
    self.raise_routing_exception(req)
  File "/home/ubuntu/miniconda3/lib/python3.5/site-packages/flask/app.py", line 1600, in raise_routing_exception
    raise request.routing_exception
  File "/home/ubuntu/miniconda3/lib/python3.5/site-packages/flask/ctx.py", line 294, in match_request
    self.url_adapter.match(return_rule=True)
  File "/home/ubuntu/miniconda3/lib/python3.5/site-packages/werkzeug/routing.py", line 1563, in match
    raise NotFound()
werkzeug.exceptions.NotFound: 404: Not Found

During handling of the above exception, another exception occurred:

Traceback (most recent call last):
  File "/home/ubuntu/miniconda3/lib/python3.5/site-packages/flask/app.py", line 1988, in wsgi_app
    response = self.full_dispatch_request()
  File "/home/ubuntu/miniconda3/lib/python3.5/site-packages/flask/app.py", line 1641, in full_dispatch_request
    rv = self.handle_user_exception(e)
  File "/home/ubuntu/miniconda3/lib/python3.5/site-packages/flask/app.py", line 1539, in handle_user_exception
    return self.handle_http_exception(e)
  File "/home/ubuntu/miniconda3/lib/python3.5/site-packages/flask/app.py", line 1498, in handle_http_exception
    return handler(e)
  File "/home/ubuntu/workspace/finance/app/views.py", line 40, in not_found_error
    return render_template('404.html'), 404
  File "/home/ubuntu/miniconda3/lib/python3.5/site-packages/flask/templating.py", line 134, in render_template
    context, ctx.app)
  File "/home/ubuntu/miniconda3/lib/python3.5/site-packages/flask/templating.py", line 116, in _render
    rv = template.render(context)
  File "/home/ubuntu/miniconda3/lib/python3.5/site-packages/jinja2/environment.py", line 989, in render
    return self.environment.handle_exception(exc_info, True)
  File "/home/ubuntu/miniconda3/lib/python3.5/site-packages/jinja2/environment.py", line 754, in handle_exception
    reraise(exc_type, exc_value, tb)
  File "/home/ubuntu/miniconda3/lib/python3.5/site-packages/jinja2/_compat.py", line 37, in reraise
    raise value.with_traceback(tb)
  File "/home/ubuntu/workspace/finance/app/templates/404.html", line 2, in top-level template code
    {% extends "base.html" %}
  File "/home/ubuntu/workspace/finance/app/templates/base.html", line 34, in top-level template code
    {% block content %}{% endblock %}
  File "/home/ubuntu/workspace/finance/app/templates/404.html", line 6, in block "content"
    <p><a href="{{ url_for('') }}">Back</a></p>
  File "/home/ubuntu/miniconda3/lib/python3.5/site-packages/flask/helpers.py", line 332, in url_for
    return appctx.app.handle_url_build_error(error, endpoint, values)
  File "/home/ubuntu/miniconda3/lib/python3.5/site-packages/flask/app.py", line 1811, in handle_url_build_error
    reraise(exc_type, exc_value, tb)
  File "/home/ubuntu/miniconda3/lib/python3.5/site-packages/flask/_compat.py", line 33, in reraise
    raise value
  File "/home/ubuntu/miniconda3/lib/python3.5/site-packages/flask/helpers.py", line 322, in url_for
    force_external=external)
  File "/home/ubuntu/miniconda3/lib/python3.5/site-packages/werkzeug/routing.py", line 1758, in build
    raise BuildError(endpoint, values, method, self)
werkzeug.routing.BuildError: Could not build url for endpoint ''. Did you mean 'equity_screener' instead?
2016-10-17 01:26:22,428 INFO: finance hub startup [in /home/ubuntu/workspace/finance/app/__init__.py:49]
2016-10-17 01:26:26,342 ERROR: Exception on /favicon.ico [GET] [in /home/ubuntu/miniconda3/lib/python3.5/site-packages/flask/app.py:1587]
Traceback (most recent call last):
  File "/home/ubuntu/miniconda3/lib/python3.5/site-packages/flask/app.py", line 1639, in full_dispatch_request
    rv = self.dispatch_request()
  File "/home/ubuntu/miniconda3/lib/python3.5/site-packages/flask/app.py", line 1617, in dispatch_request
    self.raise_routing_exception(req)
  File "/home/ubuntu/miniconda3/lib/python3.5/site-packages/flask/app.py", line 1600, in raise_routing_exception
    raise request.routing_exception
  File "/home/ubuntu/miniconda3/lib/python3.5/site-packages/flask/ctx.py", line 294, in match_request
    self.url_adapter.match(return_rule=True)
  File "/home/ubuntu/miniconda3/lib/python3.5/site-packages/werkzeug/routing.py", line 1563, in match
    raise NotFound()
werkzeug.exceptions.NotFound: 404: Not Found

During handling of the above exception, another exception occurred:

Traceback (most recent call last):
  File "/home/ubuntu/miniconda3/lib/python3.5/site-packages/flask/app.py", line 1988, in wsgi_app
    response = self.full_dispatch_request()
  File "/home/ubuntu/miniconda3/lib/python3.5/site-packages/flask/app.py", line 1641, in full_dispatch_request
    rv = self.handle_user_exception(e)
  File "/home/ubuntu/miniconda3/lib/python3.5/site-packages/flask/app.py", line 1539, in handle_user_exception
    return self.handle_http_exception(e)
  File "/home/ubuntu/miniconda3/lib/python3.5/site-packages/flask/app.py", line 1498, in handle_http_exception
    return handler(e)
  File "/home/ubuntu/workspace/finance/app/views.py", line 40, in not_found_error
    return render_template('404.html'), 404
  File "/home/ubuntu/miniconda3/lib/python3.5/site-packages/flask/templating.py", line 134, in render_template
    context, ctx.app)
  File "/home/ubuntu/miniconda3/lib/python3.5/site-packages/flask/templating.py", line 116, in _render
    rv = template.render(context)
  File "/home/ubuntu/miniconda3/lib/python3.5/site-packages/jinja2/environment.py", line 989, in render
    return self.environment.handle_exception(exc_info, True)
  File "/home/ubuntu/miniconda3/lib/python3.5/site-packages/jinja2/environment.py", line 754, in handle_exception
    reraise(exc_type, exc_value, tb)
  File "/home/ubuntu/miniconda3/lib/python3.5/site-packages/jinja2/_compat.py", line 37, in reraise
    raise value.with_traceback(tb)
  File "/home/ubuntu/workspace/finance/app/templates/404.html", line 2, in top-level template code
    {% extends "base.html" %}
  File "/home/ubuntu/workspace/finance/app/templates/base.html", line 34, in top-level template code
    {% block content %}{% endblock %}
  File "/home/ubuntu/workspace/finance/app/templates/404.html", line 6, in block "content"
    <p><a href="{{ url_for('') }}">Back</a></p>
  File "/home/ubuntu/miniconda3/lib/python3.5/site-packages/flask/helpers.py", line 332, in url_for
    return appctx.app.handle_url_build_error(error, endpoint, values)
  File "/home/ubuntu/miniconda3/lib/python3.5/site-packages/flask/app.py", line 1811, in handle_url_build_error
    reraise(exc_type, exc_value, tb)
  File "/home/ubuntu/miniconda3/lib/python3.5/site-packages/flask/_compat.py", line 33, in reraise
    raise value
  File "/home/ubuntu/miniconda3/lib/python3.5/site-packages/flask/helpers.py", line 322, in url_for
    force_external=external)
  File "/home/ubuntu/miniconda3/lib/python3.5/site-packages/werkzeug/routing.py", line 1758, in build
    raise BuildError(endpoint, values, method, self)
werkzeug.routing.BuildError: Could not build url for endpoint ''. Did you mean 'equity_screener' instead?
2016-10-17 01:26:28,596 ERROR: Exception on /favicon.ico [GET] [in /home/ubuntu/miniconda3/lib/python3.5/site-packages/flask/app.py:1587]
Traceback (most recent call last):
  File "/home/ubuntu/miniconda3/lib/python3.5/site-packages/flask/app.py", line 1639, in full_dispatch_request
    rv = self.dispatch_request()
  File "/home/ubuntu/miniconda3/lib/python3.5/site-packages/flask/app.py", line 1617, in dispatch_request
    self.raise_routing_exception(req)
  File "/home/ubuntu/miniconda3/lib/python3.5/site-packages/flask/app.py", line 1600, in raise_routing_exception
    raise request.routing_exception
  File "/home/ubuntu/miniconda3/lib/python3.5/site-packages/flask/ctx.py", line 294, in match_request
    self.url_adapter.match(return_rule=True)
  File "/home/ubuntu/miniconda3/lib/python3.5/site-packages/werkzeug/routing.py", line 1563, in match
    raise NotFound()
werkzeug.exceptions.NotFound: 404: Not Found

During handling of the above exception, another exception occurred:

Traceback (most recent call last):
  File "/home/ubuntu/miniconda3/lib/python3.5/site-packages/flask/app.py", line 1988, in wsgi_app
    response = self.full_dispatch_request()
  File "/home/ubuntu/miniconda3/lib/python3.5/site-packages/flask/app.py", line 1641, in full_dispatch_request
    rv = self.handle_user_exception(e)
  File "/home/ubuntu/miniconda3/lib/python3.5/site-packages/flask/app.py", line 1539, in handle_user_exception
    return self.handle_http_exception(e)
  File "/home/ubuntu/miniconda3/lib/python3.5/site-packages/flask/app.py", line 1498, in handle_http_exception
    return handler(e)
  File "/home/ubuntu/workspace/finance/app/views.py", line 40, in not_found_error
    return render_template('404.html'), 404
  File "/home/ubuntu/miniconda3/lib/python3.5/site-packages/flask/templating.py", line 134, in render_template
    context, ctx.app)
  File "/home/ubuntu/miniconda3/lib/python3.5/site-packages/flask/templating.py", line 116, in _render
    rv = template.render(context)
  File "/home/ubuntu/miniconda3/lib/python3.5/site-packages/jinja2/environment.py", line 989, in render
    return self.environment.handle_exception(exc_info, True)
  File "/home/ubuntu/miniconda3/lib/python3.5/site-packages/jinja2/environment.py", line 754, in handle_exception
    reraise(exc_type, exc_value, tb)
  File "/home/ubuntu/miniconda3/lib/python3.5/site-packages/jinja2/_compat.py", line 37, in reraise
    raise value.with_traceback(tb)
  File "/home/ubuntu/workspace/finance/app/templates/404.html", line 2, in top-level template code
    {% extends "base.html" %}
  File "/home/ubuntu/workspace/finance/app/templates/base.html", line 34, in top-level template code
    {% block content %}{% endblock %}
  File "/home/ubuntu/workspace/finance/app/templates/404.html", line 6, in block "content"
    <p><a href="{{ url_for('') }}">Back</a></p>
  File "/home/ubuntu/miniconda3/lib/python3.5/site-packages/flask/helpers.py", line 332, in url_for
    return appctx.app.handle_url_build_error(error, endpoint, values)
  File "/home/ubuntu/miniconda3/lib/python3.5/site-packages/flask/app.py", line 1811, in handle_url_build_error
    reraise(exc_type, exc_value, tb)
  File "/home/ubuntu/miniconda3/lib/python3.5/site-packages/flask/_compat.py", line 33, in reraise
    raise value
  File "/home/ubuntu/miniconda3/lib/python3.5/site-packages/flask/helpers.py", line 322, in url_for
    force_external=external)
  File "/home/ubuntu/miniconda3/lib/python3.5/site-packages/werkzeug/routing.py", line 1758, in build
    raise BuildError(endpoint, values, method, self)
werkzeug.routing.BuildError: Could not build url for endpoint ''. Did you mean 'equity_screener' instead?
2016-10-17 01:26:38,450 ERROR: Exception on /equity_screener [POST] [in /home/ubuntu/miniconda3/lib/python3.5/site-packages/flask/app.py:1587]
Traceback (most recent call last):
  File "/home/ubuntu/miniconda3/lib/python3.5/site-packages/flask/app.py", line 1988, in wsgi_app
    response = self.full_dispatch_request()
  File "/home/ubuntu/miniconda3/lib/python3.5/site-packages/flask/app.py", line 1641, in full_dispatch_request
    rv = self.handle_user_exception(e)
  File "/home/ubuntu/miniconda3/lib/python3.5/site-packages/flask/app.py", line 1544, in handle_user_exception
    reraise(exc_type, exc_value, tb)
  File "/home/ubuntu/miniconda3/lib/python3.5/site-packages/flask/_compat.py", line 33, in reraise
    raise value
  File "/home/ubuntu/miniconda3/lib/python3.5/site-packages/flask/app.py", line 1639, in full_dispatch_request
    rv = self.dispatch_request()
  File "/home/ubuntu/miniconda3/lib/python3.5/site-packages/flask/app.py", line 1625, in dispatch_request
    return self.view_functions[rule.endpoint](**req.view_args)
  File "/home/ubuntu/workspace/finance/app/views.py", line 25, in equity_screener
    eqsc_post(request)
  File "/home/ubuntu/workspace/finance/app/equity_screener/equity_screener.py", line 11, in post
    run_screening(filters=filters, sim=False)
  File "/home/ubuntu/workspace/finance/app/equity_screener/equity_screener.py", line 44, in run_screening
    for e in eqs:
NameError: name 'eqs' is not defined
2016-10-17 01:30:22,008 INFO: finance hub startup [in /home/ubuntu/workspace/finance/app/__init__.py:49]
2016-10-17 01:30:26,383 ERROR: Exception on /favicon.ico [GET] [in /home/ubuntu/miniconda3/lib/python3.5/site-packages/flask/app.py:1587]
Traceback (most recent call last):
  File "/home/ubuntu/miniconda3/lib/python3.5/site-packages/flask/app.py", line 1639, in full_dispatch_request
    rv = self.dispatch_request()
  File "/home/ubuntu/miniconda3/lib/python3.5/site-packages/flask/app.py", line 1617, in dispatch_request
    self.raise_routing_exception(req)
  File "/home/ubuntu/miniconda3/lib/python3.5/site-packages/flask/app.py", line 1600, in raise_routing_exception
    raise request.routing_exception
  File "/home/ubuntu/miniconda3/lib/python3.5/site-packages/flask/ctx.py", line 294, in match_request
    self.url_adapter.match(return_rule=True)
  File "/home/ubuntu/miniconda3/lib/python3.5/site-packages/werkzeug/routing.py", line 1563, in match
    raise NotFound()
werkzeug.exceptions.NotFound: 404: Not Found

During handling of the above exception, another exception occurred:

Traceback (most recent call last):
  File "/home/ubuntu/miniconda3/lib/python3.5/site-packages/flask/app.py", line 1988, in wsgi_app
    response = self.full_dispatch_request()
  File "/home/ubuntu/miniconda3/lib/python3.5/site-packages/flask/app.py", line 1641, in full_dispatch_request
    rv = self.handle_user_exception(e)
  File "/home/ubuntu/miniconda3/lib/python3.5/site-packages/flask/app.py", line 1539, in handle_user_exception
    return self.handle_http_exception(e)
  File "/home/ubuntu/miniconda3/lib/python3.5/site-packages/flask/app.py", line 1498, in handle_http_exception
    return handler(e)
  File "/home/ubuntu/workspace/finance/app/views.py", line 40, in not_found_error
    return render_template('404.html'), 404
  File "/home/ubuntu/miniconda3/lib/python3.5/site-packages/flask/templating.py", line 134, in render_template
    context, ctx.app)
  File "/home/ubuntu/miniconda3/lib/python3.5/site-packages/flask/templating.py", line 116, in _render
    rv = template.render(context)
  File "/home/ubuntu/miniconda3/lib/python3.5/site-packages/jinja2/environment.py", line 989, in render
    return self.environment.handle_exception(exc_info, True)
  File "/home/ubuntu/miniconda3/lib/python3.5/site-packages/jinja2/environment.py", line 754, in handle_exception
    reraise(exc_type, exc_value, tb)
  File "/home/ubuntu/miniconda3/lib/python3.5/site-packages/jinja2/_compat.py", line 37, in reraise
    raise value.with_traceback(tb)
  File "/home/ubuntu/workspace/finance/app/templates/404.html", line 2, in top-level template code
    {% extends "base.html" %}
  File "/home/ubuntu/workspace/finance/app/templates/base.html", line 34, in top-level template code
    {% block content %}{% endblock %}
  File "/home/ubuntu/workspace/finance/app/templates/404.html", line 6, in block "content"
    <p><a href="{{ url_for('') }}">Back</a></p>
  File "/home/ubuntu/miniconda3/lib/python3.5/site-packages/flask/helpers.py", line 332, in url_for
    return appctx.app.handle_url_build_error(error, endpoint, values)
  File "/home/ubuntu/miniconda3/lib/python3.5/site-packages/flask/app.py", line 1811, in handle_url_build_error
    reraise(exc_type, exc_value, tb)
  File "/home/ubuntu/miniconda3/lib/python3.5/site-packages/flask/_compat.py", line 33, in reraise
    raise value
  File "/home/ubuntu/miniconda3/lib/python3.5/site-packages/flask/helpers.py", line 322, in url_for
    force_external=external)
  File "/home/ubuntu/miniconda3/lib/python3.5/site-packages/werkzeug/routing.py", line 1758, in build
    raise BuildError(endpoint, values, method, self)
werkzeug.routing.BuildError: Could not build url for endpoint ''. Did you mean 'equity_screener' instead?
2016-10-17 01:30:28,107 ERROR: Exception on /favicon.ico [GET] [in /home/ubuntu/miniconda3/lib/python3.5/site-packages/flask/app.py:1587]
Traceback (most recent call last):
  File "/home/ubuntu/miniconda3/lib/python3.5/site-packages/flask/app.py", line 1639, in full_dispatch_request
    rv = self.dispatch_request()
  File "/home/ubuntu/miniconda3/lib/python3.5/site-packages/flask/app.py", line 1617, in dispatch_request
    self.raise_routing_exception(req)
  File "/home/ubuntu/miniconda3/lib/python3.5/site-packages/flask/app.py", line 1600, in raise_routing_exception
    raise request.routing_exception
  File "/home/ubuntu/miniconda3/lib/python3.5/site-packages/flask/ctx.py", line 294, in match_request
    self.url_adapter.match(return_rule=True)
  File "/home/ubuntu/miniconda3/lib/python3.5/site-packages/werkzeug/routing.py", line 1563, in match
    raise NotFound()
werkzeug.exceptions.NotFound: 404: Not Found

During handling of the above exception, another exception occurred:

Traceback (most recent call last):
  File "/home/ubuntu/miniconda3/lib/python3.5/site-packages/flask/app.py", line 1988, in wsgi_app
    response = self.full_dispatch_request()
  File "/home/ubuntu/miniconda3/lib/python3.5/site-packages/flask/app.py", line 1641, in full_dispatch_request
    rv = self.handle_user_exception(e)
  File "/home/ubuntu/miniconda3/lib/python3.5/site-packages/flask/app.py", line 1539, in handle_user_exception
    return self.handle_http_exception(e)
  File "/home/ubuntu/miniconda3/lib/python3.5/site-packages/flask/app.py", line 1498, in handle_http_exception
    return handler(e)
  File "/home/ubuntu/workspace/finance/app/views.py", line 40, in not_found_error
    return render_template('404.html'), 404
  File "/home/ubuntu/miniconda3/lib/python3.5/site-packages/flask/templating.py", line 134, in render_template
    context, ctx.app)
  File "/home/ubuntu/miniconda3/lib/python3.5/site-packages/flask/templating.py", line 116, in _render
    rv = template.render(context)
  File "/home/ubuntu/miniconda3/lib/python3.5/site-packages/jinja2/environment.py", line 989, in render
    return self.environment.handle_exception(exc_info, True)
  File "/home/ubuntu/miniconda3/lib/python3.5/site-packages/jinja2/environment.py", line 754, in handle_exception
    reraise(exc_type, exc_value, tb)
  File "/home/ubuntu/miniconda3/lib/python3.5/site-packages/jinja2/_compat.py", line 37, in reraise
    raise value.with_traceback(tb)
  File "/home/ubuntu/workspace/finance/app/templates/404.html", line 2, in top-level template code
    {% extends "base.html" %}
  File "/home/ubuntu/workspace/finance/app/templates/base.html", line 34, in top-level template code
    {% block content %}{% endblock %}
  File "/home/ubuntu/workspace/finance/app/templates/404.html", line 6, in block "content"
    <p><a href="{{ url_for('') }}">Back</a></p>
  File "/home/ubuntu/miniconda3/lib/python3.5/site-packages/flask/helpers.py", line 332, in url_for
    return appctx.app.handle_url_build_error(error, endpoint, values)
  File "/home/ubuntu/miniconda3/lib/python3.5/site-packages/flask/app.py", line 1811, in handle_url_build_error
    reraise(exc_type, exc_value, tb)
  File "/home/ubuntu/miniconda3/lib/python3.5/site-packages/flask/_compat.py", line 33, in reraise
    raise value
  File "/home/ubuntu/miniconda3/lib/python3.5/site-packages/flask/helpers.py", line 322, in url_for
    force_external=external)
  File "/home/ubuntu/miniconda3/lib/python3.5/site-packages/werkzeug/routing.py", line 1758, in build
    raise BuildError(endpoint, values, method, self)
werkzeug.routing.BuildError: Could not build url for endpoint ''. Did you mean 'equity_screener' instead?
2016-10-17 01:31:04,793 INFO: finance hub startup [in /home/ubuntu/workspace/finance/app/__init__.py:49]
2016-10-17 01:31:09,081 ERROR: Exception on /favicon.ico [GET] [in /home/ubuntu/miniconda3/lib/python3.5/site-packages/flask/app.py:1587]
Traceback (most recent call last):
  File "/home/ubuntu/miniconda3/lib/python3.5/site-packages/flask/app.py", line 1639, in full_dispatch_request
    rv = self.dispatch_request()
  File "/home/ubuntu/miniconda3/lib/python3.5/site-packages/flask/app.py", line 1617, in dispatch_request
    self.raise_routing_exception(req)
  File "/home/ubuntu/miniconda3/lib/python3.5/site-packages/flask/app.py", line 1600, in raise_routing_exception
    raise request.routing_exception
  File "/home/ubuntu/miniconda3/lib/python3.5/site-packages/flask/ctx.py", line 294, in match_request
    self.url_adapter.match(return_rule=True)
  File "/home/ubuntu/miniconda3/lib/python3.5/site-packages/werkzeug/routing.py", line 1563, in match
    raise NotFound()
werkzeug.exceptions.NotFound: 404: Not Found

During handling of the above exception, another exception occurred:

Traceback (most recent call last):
  File "/home/ubuntu/miniconda3/lib/python3.5/site-packages/flask/app.py", line 1988, in wsgi_app
    response = self.full_dispatch_request()
  File "/home/ubuntu/miniconda3/lib/python3.5/site-packages/flask/app.py", line 1641, in full_dispatch_request
    rv = self.handle_user_exception(e)
  File "/home/ubuntu/miniconda3/lib/python3.5/site-packages/flask/app.py", line 1539, in handle_user_exception
    return self.handle_http_exception(e)
  File "/home/ubuntu/miniconda3/lib/python3.5/site-packages/flask/app.py", line 1498, in handle_http_exception
    return handler(e)
  File "/home/ubuntu/workspace/finance/app/views.py", line 40, in not_found_error
    return render_template('404.html'), 404
  File "/home/ubuntu/miniconda3/lib/python3.5/site-packages/flask/templating.py", line 134, in render_template
    context, ctx.app)
  File "/home/ubuntu/miniconda3/lib/python3.5/site-packages/flask/templating.py", line 116, in _render
    rv = template.render(context)
  File "/home/ubuntu/miniconda3/lib/python3.5/site-packages/jinja2/environment.py", line 989, in render
    return self.environment.handle_exception(exc_info, True)
  File "/home/ubuntu/miniconda3/lib/python3.5/site-packages/jinja2/environment.py", line 754, in handle_exception
    reraise(exc_type, exc_value, tb)
  File "/home/ubuntu/miniconda3/lib/python3.5/site-packages/jinja2/_compat.py", line 37, in reraise
    raise value.with_traceback(tb)
  File "/home/ubuntu/workspace/finance/app/templates/404.html", line 2, in top-level template code
    {% extends "base.html" %}
  File "/home/ubuntu/workspace/finance/app/templates/base.html", line 34, in top-level template code
    {% block content %}{% endblock %}
  File "/home/ubuntu/workspace/finance/app/templates/404.html", line 6, in block "content"
    <p><a href="{{ url_for('') }}">Back</a></p>
  File "/home/ubuntu/miniconda3/lib/python3.5/site-packages/flask/helpers.py", line 332, in url_for
    return appctx.app.handle_url_build_error(error, endpoint, values)
  File "/home/ubuntu/miniconda3/lib/python3.5/site-packages/flask/app.py", line 1811, in handle_url_build_error
    reraise(exc_type, exc_value, tb)
  File "/home/ubuntu/miniconda3/lib/python3.5/site-packages/flask/_compat.py", line 33, in reraise
    raise value
  File "/home/ubuntu/miniconda3/lib/python3.5/site-packages/flask/helpers.py", line 322, in url_for
    force_external=external)
  File "/home/ubuntu/miniconda3/lib/python3.5/site-packages/werkzeug/routing.py", line 1758, in build
    raise BuildError(endpoint, values, method, self)
werkzeug.routing.BuildError: Could not build url for endpoint ''. Did you mean 'equity_screener' instead?
2016-10-17 01:31:52,308 INFO: finance hub startup [in /home/ubuntu/workspace/finance/app/__init__.py:49]
2016-10-17 01:32:53,029 INFO: finance hub startup [in /home/ubuntu/workspace/finance/app/__init__.py:49]
2016-10-17 01:34:57,060 INFO: finance hub startup [in /home/ubuntu/workspace/finance/app/__init__.py:49]
2016-10-17 01:36:01,547 ERROR: Exception on /equity_screener [POST] [in /home/ubuntu/miniconda3/lib/python3.5/site-packages/flask/app.py:1587]
Traceback (most recent call last):
  File "/home/ubuntu/miniconda3/lib/python3.5/site-packages/flask/app.py", line 1988, in wsgi_app
    response = self.full_dispatch_request()
  File "/home/ubuntu/miniconda3/lib/python3.5/site-packages/flask/app.py", line 1639, in full_dispatch_request
    rv = self.dispatch_request()
  File "/home/ubuntu/miniconda3/lib/python3.5/site-packages/flask/app.py", line 1544, in handle_user_exception
    reraise(exc_type, exc_value, tb)
  File "/home/ubuntu/miniconda3/lib/python3.5/site-packages/flask/_compat.py", line 33, in reraise
    raise value
  File "/home/ubuntu/miniconda3/lib/python3.5/site-packages/flask/app.py", line 1639, in full_dispatch_request
    rv = self.dispatch_request()
  File "/home/ubuntu/miniconda3/lib/python3.5/site-packages/flask/app.py", line 1625, in dispatch_request
    return self.view_functions[rule.endpoint](**req.view_args)
  File "/home/ubuntu/workspace/finance/app/views.py", line 25, in equity_screener
    eqsc_post(request)
  File "/home/ubuntu/workspace/finance/app/equity_screener/equity_screener.py", line 14, in post
    get_data(reset_ticks=False)
  File "/home/ubuntu/miniconda3/lib/python3.5/bdb.py", line 52, in trace_dispatch
    return self.dispatch_return(frame, arg)
  File "/home/ubuntu/miniconda3/lib/python3.5/bdb.py", line 96, in dispatch_return
    if self.quitting: raise BdbQuit
bdb.BdbQuit
2016-10-17 01:36:02,920 ERROR: Exception on /equity_screener [POST] [in /home/ubuntu/miniconda3/lib/python3.5/site-packages/flask/app.py:1587]
Traceback (most recent call last):
  File "/home/ubuntu/miniconda3/lib/python3.5/site-packages/flask/app.py", line 1988, in wsgi_app
    response = self.full_dispatch_request()
  File "/home/ubuntu/miniconda3/lib/python3.5/site-packages/flask/app.py", line 1639, in full_dispatch_request
    rv = self.dispatch_request()
  File "/home/ubuntu/miniconda3/lib/python3.5/site-packages/flask/app.py", line 1544, in handle_user_exception
    reraise(exc_type, exc_value, tb)
  File "/home/ubuntu/miniconda3/lib/python3.5/site-packages/flask/_compat.py", line 33, in reraise
    raise value
  File "/home/ubuntu/miniconda3/lib/python3.5/site-packages/flask/app.py", line 1639, in full_dispatch_request
    rv = self.dispatch_request()
  File "/home/ubuntu/miniconda3/lib/python3.5/site-packages/flask/app.py", line 1625, in dispatch_request
    return self.view_functions[rule.endpoint](**req.view_args)
  File "/home/ubuntu/workspace/finance/app/views.py", line 25, in equity_screener
    eqsc_post(request)
  File "/home/ubuntu/workspace/finance/app/equity_screener/equity_screener.py", line 9, in post
    # filters = getFilters(req=request)
  File "/home/ubuntu/workspace/finance/app/equity_screener/equity_screener.py", line 9, in post
    # filters = getFilters(req=request)
  File "/home/ubuntu/miniconda3/lib/python3.5/bdb.py", line 48, in trace_dispatch
    return self.dispatch_line(frame)
  File "/home/ubuntu/miniconda3/lib/python3.5/bdb.py", line 67, in dispatch_line
    if self.quitting: raise BdbQuit
bdb.BdbQuit
2016-10-17 01:36:06,451 INFO: finance hub startup [in /home/ubuntu/workspace/finance/app/__init__.py:49]
2016-10-17 01:39:15,187 INFO: finance hub startup [in /home/ubuntu/workspace/finance/app/__init__.py:49]
2016-10-17 01:40:07,576 INFO: finance hub startup [in /home/ubuntu/workspace/finance/app/__init__.py:49]
2016-10-17 01:40:19,732 INFO: finance hub startup [in /home/ubuntu/workspace/finance/app/__init__.py:49]
2016-10-17 01:41:19,104 ERROR: Exception on /equity_screener [POST] [in /home/ubuntu/miniconda3/lib/python3.5/site-packages/flask/app.py:1587]
Traceback (most recent call last):
  File "/home/ubuntu/miniconda3/lib/python3.5/site-packages/flask/app.py", line 1988, in wsgi_app
    response = self.full_dispatch_request()
  File "/home/ubuntu/miniconda3/lib/python3.5/site-packages/flask/app.py", line 1639, in full_dispatch_request
    rv = self.dispatch_request()
  File "/home/ubuntu/miniconda3/lib/python3.5/site-packages/flask/app.py", line 1544, in handle_user_exception
    reraise(exc_type, exc_value, tb)
  File "/home/ubuntu/miniconda3/lib/python3.5/site-packages/flask/_compat.py", line 33, in reraise
    raise value
  File "/home/ubuntu/miniconda3/lib/python3.5/site-packages/flask/app.py", line 1639, in full_dispatch_request
    rv = self.dispatch_request()
  File "/home/ubuntu/miniconda3/lib/python3.5/site-packages/flask/app.py", line 1625, in dispatch_request
    return self.view_functions[rule.endpoint](**req.view_args)
  File "/home/ubuntu/workspace/finance/app/views.py", line 25, in equity_screener
    eqsc_post(request)
  File "/home/ubuntu/workspace/finance/app/equity_screener/equity_screener.py", line 14, in post
    if request.form['action'] == 'get_data':
  File "/home/ubuntu/workspace/finance/app/equity_screener/equity_screener.py", line 14, in post
    if request.form['action'] == 'get_data':
  File "/home/ubuntu/miniconda3/lib/python3.5/bdb.py", line 48, in trace_dispatch
    return self.dispatch_line(frame)
  File "/home/ubuntu/miniconda3/lib/python3.5/bdb.py", line 67, in dispatch_line
    if self.quitting: raise BdbQuit
bdb.BdbQuit
2016-10-17 01:41:45,105 INFO: finance hub startup [in /home/ubuntu/workspace/finance/app/__init__.py:49]
2016-10-17 01:49:11,267 ERROR: Exception on /equity_screener [POST] [in /home/ubuntu/miniconda3/lib/python3.5/site-packages/flask/app.py:1587]
Traceback (most recent call last):
  File "/home/ubuntu/miniconda3/lib/python3.5/site-packages/flask/app.py", line 1988, in wsgi_app
    response = self.full_dispatch_request()
  File "/home/ubuntu/miniconda3/lib/python3.5/site-packages/flask/app.py", line 1639, in full_dispatch_request
    rv = self.dispatch_request()
  File "/home/ubuntu/miniconda3/lib/python3.5/site-packages/flask/app.py", line 1544, in handle_user_exception
    reraise(exc_type, exc_value, tb)
  File "/home/ubuntu/miniconda3/lib/python3.5/site-packages/flask/_compat.py", line 33, in reraise
    raise value
  File "/home/ubuntu/miniconda3/lib/python3.5/site-packages/flask/app.py", line 1639, in full_dispatch_request
    rv = self.dispatch_request()
  File "/home/ubuntu/miniconda3/lib/python3.5/site-packages/flask/app.py", line 1625, in dispatch_request
    return self.view_functions[rule.endpoint](**req.view_args)
  File "/home/ubuntu/workspace/finance/app/views.py", line 25, in equity_screener
    eqsc_post(request)
  File "/home/ubuntu/workspace/finance/app/equity_screener/equity_screener.py", line 14, in post
    if request.form['action'] == 'get_data':
  File "/home/ubuntu/miniconda3/lib/python3.5/bdb.py", line 52, in trace_dispatch
    return self.dispatch_return(frame, arg)
  File "/home/ubuntu/miniconda3/lib/python3.5/bdb.py", line 96, in dispatch_return
    if self.quitting: raise BdbQuit
bdb.BdbQuit
2016-10-17 01:49:12,190 ERROR: Exception on /equity_screener [POST] [in /home/ubuntu/miniconda3/lib/python3.5/site-packages/flask/app.py:1587]
Traceback (most recent call last):
  File "/home/ubuntu/miniconda3/lib/python3.5/site-packages/flask/app.py", line 1988, in wsgi_app
    response = self.full_dispatch_request()
  File "/home/ubuntu/miniconda3/lib/python3.5/site-packages/flask/app.py", line 1639, in full_dispatch_request
    rv = self.dispatch_request()
  File "/home/ubuntu/miniconda3/lib/python3.5/site-packages/flask/app.py", line 1544, in handle_user_exception
    reraise(exc_type, exc_value, tb)
  File "/home/ubuntu/miniconda3/lib/python3.5/site-packages/flask/_compat.py", line 33, in reraise
    raise value
  File "/home/ubuntu/miniconda3/lib/python3.5/site-packages/flask/app.py", line 1639, in full_dispatch_request
    rv = self.dispatch_request()
  File "/home/ubuntu/miniconda3/lib/python3.5/site-packages/flask/app.py", line 1625, in dispatch_request
    return self.view_functions[rule.endpoint](**req.view_args)
  File "/home/ubuntu/workspace/finance/app/views.py", line 25, in equity_screener
    eqsc_post(request)
  File "/home/ubuntu/workspace/finance/app/equity_screener/equity_screener.py", line 9, in post
    if request.form['action'] == 'run_screening':
  File "/home/ubuntu/workspace/finance/app/equity_screener/equity_screener.py", line 9, in post
    if request.form['action'] == 'run_screening':
  File "/home/ubuntu/miniconda3/lib/python3.5/bdb.py", line 48, in trace_dispatch
    return self.dispatch_line(frame)
  File "/home/ubuntu/miniconda3/lib/python3.5/bdb.py", line 67, in dispatch_line
    if self.quitting: raise BdbQuit
bdb.BdbQuit
2016-10-17 01:49:37,533 ERROR: Exception on /equity_screener [POST] [in /home/ubuntu/miniconda3/lib/python3.5/site-packages/flask/app.py:1587]
Traceback (most recent call last):
  File "/home/ubuntu/miniconda3/lib/python3.5/site-packages/flask/app.py", line 1988, in wsgi_app
    response = self.full_dispatch_request()
  File "/home/ubuntu/miniconda3/lib/python3.5/site-packages/flask/app.py", line 1641, in full_dispatch_request
    rv = self.handle_user_exception(e)
  File "/home/ubuntu/miniconda3/lib/python3.5/site-packages/flask/app.py", line 1544, in handle_user_exception
    reraise(exc_type, exc_value, tb)
  File "/home/ubuntu/miniconda3/lib/python3.5/site-packages/flask/_compat.py", line 33, in reraise
    raise value
  File "/home/ubuntu/miniconda3/lib/python3.5/site-packages/flask/app.py", line 1639, in full_dispatch_request
    rv = self.dispatch_request()
  File "/home/ubuntu/miniconda3/lib/python3.5/site-packages/flask/app.py", line 1625, in dispatch_request
    return self.view_functions[rule.endpoint](**req.view_args)
  File "/home/ubuntu/workspace/finance/app/views.py", line 25, in equity_screener
    eqsc_post(request)
  File "/home/ubuntu/workspace/finance/app/equity_screener/equity_screener.py", line 15, in post
    get_data(reset_ticks=False)
  File "/home/ubuntu/workspace/finance/app/equity_screener/equity_screener.py", line 23, in get_data
    eqs = []
  File "/home/ubuntu/workspace/finance/app/equity_screener/equity_stats.py", line 32, in setColumns
    column_map[t_tup[0]] = t_tup[1]
IndexError: list index out of range
2016-10-17 13:23:47,792 INFO: finance hub startup [in /home/ubuntu/workspace/finance/app/__init__.py:49]
2016-10-17 13:25:11,339 ERROR: Exception on /equity_screener [POST] [in /home/ubuntu/miniconda3/lib/python3.5/site-packages/flask/app.py:1587]
Traceback (most recent call last):
  File "/home/ubuntu/miniconda3/lib/python3.5/site-packages/flask/app.py", line 1988, in wsgi_app
    response = self.full_dispatch_request()
  File "/home/ubuntu/miniconda3/lib/python3.5/site-packages/flask/app.py", line 1639, in full_dispatch_request
    rv = self.dispatch_request()
  File "/home/ubuntu/miniconda3/lib/python3.5/site-packages/flask/app.py", line 1544, in handle_user_exception
    reraise(exc_type, exc_value, tb)
  File "/home/ubuntu/miniconda3/lib/python3.5/site-packages/flask/_compat.py", line 33, in reraise
    raise value
  File "/home/ubuntu/miniconda3/lib/python3.5/site-packages/flask/app.py", line 1639, in full_dispatch_request
    rv = self.dispatch_request()
  File "/home/ubuntu/miniconda3/lib/python3.5/site-packages/flask/app.py", line 1625, in dispatch_request
    return self.view_functions[rule.endpoint](**req.view_args)
  File "/home/ubuntu/workspace/finance/app/views.py", line 25, in equity_screener
    eqsc_post(request)
  File "/home/ubuntu/workspace/finance/app/equity_screener/equity_screener.py", line 15, in post
  File "/home/ubuntu/workspace/finance/app/equity_screener/equity_screener.py", line 17, in get_data
    if reset_ticks:
  File "/home/ubuntu/miniconda3/lib/python3.5/bdb.py", line 50, in trace_dispatch
    return self.dispatch_call(frame, arg)
  File "/home/ubuntu/miniconda3/lib/python3.5/bdb.py", line 83, in dispatch_call
    if self.quitting: raise BdbQuit
bdb.BdbQuit
2016-10-17 13:25:12,628 ERROR: Exception on /equity_screener [POST] [in /home/ubuntu/miniconda3/lib/python3.5/site-packages/flask/app.py:1587]
Traceback (most recent call last):
  File "/home/ubuntu/miniconda3/lib/python3.5/site-packages/flask/app.py", line 1988, in wsgi_app
    response = self.full_dispatch_request()
  File "/home/ubuntu/miniconda3/lib/python3.5/site-packages/flask/app.py", line 1639, in full_dispatch_request
    rv = self.dispatch_request()
  File "/home/ubuntu/miniconda3/lib/python3.5/site-packages/flask/app.py", line 1544, in handle_user_exception
    reraise(exc_type, exc_value, tb)
  File "/home/ubuntu/miniconda3/lib/python3.5/site-packages/flask/_compat.py", line 33, in reraise
    raise value
  File "/home/ubuntu/miniconda3/lib/python3.5/site-packages/flask/app.py", line 1639, in full_dispatch_request
    rv = self.dispatch_request()
  File "/home/ubuntu/miniconda3/lib/python3.5/site-packages/flask/app.py", line 1625, in dispatch_request
    return self.view_functions[rule.endpoint](**req.view_args)
  File "/home/ubuntu/workspace/finance/app/views.py", line 25, in equity_screener
    eqsc_post(request)
  File "/home/ubuntu/workspace/finance/app/equity_screener/equity_screener.py", line 9, in post
    # filters = getFilters(req=request)
  File "/home/ubuntu/workspace/finance/app/equity_screener/equity_screener.py", line 9, in post
    # filters = getFilters(req=request)
  File "/home/ubuntu/miniconda3/lib/python3.5/bdb.py", line 48, in trace_dispatch
    return self.dispatch_line(frame)
  File "/home/ubuntu/miniconda3/lib/python3.5/bdb.py", line 67, in dispatch_line
    if self.quitting: raise BdbQuit
bdb.BdbQuit
2016-10-17 13:29:21,404 INFO: finance hub startup [in /home/ubuntu/workspace/finance/app/__init__.py:49]
2016-10-17 13:29:43,224 ERROR: Exception on /equity_screener [POST] [in /home/ubuntu/miniconda3/lib/python3.5/site-packages/flask/app.py:1587]
Traceback (most recent call last):
  File "/home/ubuntu/miniconda3/lib/python3.5/site-packages/flask/app.py", line 1988, in wsgi_app
    response = self.full_dispatch_request()
  File "/home/ubuntu/miniconda3/lib/python3.5/site-packages/flask/app.py", line 1639, in full_dispatch_request
    rv = self.dispatch_request()
  File "/home/ubuntu/miniconda3/lib/python3.5/site-packages/flask/app.py", line 1544, in handle_user_exception
    reraise(exc_type, exc_value, tb)
  File "/home/ubuntu/miniconda3/lib/python3.5/site-packages/flask/_compat.py", line 33, in reraise
    raise value
  File "/home/ubuntu/miniconda3/lib/python3.5/site-packages/flask/app.py", line 1639, in full_dispatch_request
    rv = self.dispatch_request()
  File "/home/ubuntu/miniconda3/lib/python3.5/site-packages/flask/app.py", line 1625, in dispatch_request
    return self.view_functions[rule.endpoint](**req.view_args)
  File "/home/ubuntu/workspace/finance/app/views.py", line 25, in equity_screener
    eqsc_post(request)
  File "/home/ubuntu/workspace/finance/app/equity_screener/equity_screener.py", line 14, in post
    get_data(reset_ticks=False)
  File "/home/ubuntu/workspace/finance/app/equity_screener/equity_screener.py", line 22, in get_data
    EquityStats.setColumns()
  File "/home/ubuntu/workspace/finance/app/equity_screener/equity_screener.py", line 22, in get_data
    EquityStats.setColumns()
  File "/home/ubuntu/miniconda3/lib/python3.5/bdb.py", line 48, in trace_dispatch
    return self.dispatch_line(frame)
  File "/home/ubuntu/miniconda3/lib/python3.5/bdb.py", line 67, in dispatch_line
    if self.quitting: raise BdbQuit
bdb.BdbQuit
2016-10-17 13:29:46,187 INFO: finance hub startup [in /home/ubuntu/workspace/finance/app/__init__.py:49]
2016-10-17 13:30:34,031 ERROR: Exception on /equity_screener [POST] [in /home/ubuntu/miniconda3/lib/python3.5/site-packages/flask/app.py:1587]
Traceback (most recent call last):
  File "/home/ubuntu/miniconda3/lib/python3.5/site-packages/flask/app.py", line 1988, in wsgi_app
    response = self.full_dispatch_request()
  File "/home/ubuntu/miniconda3/lib/python3.5/site-packages/flask/app.py", line 1641, in full_dispatch_request
    rv = self.handle_user_exception(e)
  File "/home/ubuntu/miniconda3/lib/python3.5/site-packages/flask/app.py", line 1544, in handle_user_exception
    reraise(exc_type, exc_value, tb)
  File "/home/ubuntu/miniconda3/lib/python3.5/site-packages/flask/_compat.py", line 33, in reraise
    raise value
  File "/home/ubuntu/miniconda3/lib/python3.5/site-packages/flask/app.py", line 1639, in full_dispatch_request
    rv = self.dispatch_request()
  File "/home/ubuntu/miniconda3/lib/python3.5/site-packages/flask/app.py", line 1625, in dispatch_request
    return self.view_functions[rule.endpoint](**req.view_args)
  File "/home/ubuntu/workspace/finance/app/views.py", line 25, in equity_screener
    eqsc_post(request)
  File "/home/ubuntu/workspace/finance/app/equity_screener/equity_screener.py", line 14, in post
    get_data(reset_ticks=False)
  File "/home/ubuntu/workspace/finance/app/equity_screener/equity_screener.py", line 22, in get_data
    EquityStats.setColumns()
  File "/home/ubuntu/workspace/finance/app/equity_screener/equity_stats.py", line 29, in setColumns
    for line in f:
IndexError: list index out of range
2016-10-17 13:32:19,945 INFO: finance hub startup [in /home/ubuntu/workspace/finance/app/__init__.py:49]
2016-10-17 13:33:14,070 INFO: finance hub startup [in /home/ubuntu/workspace/finance/app/__init__.py:49]
2016-10-17 13:33:20,256 INFO: finance hub startup [in /home/ubuntu/workspace/finance/app/__init__.py:49]
2016-10-17 13:35:29,289 ERROR: Exception on /equity_screener [POST] [in /home/ubuntu/miniconda3/lib/python3.5/site-packages/flask/app.py:1587]
Traceback (most recent call last):
  File "/home/ubuntu/miniconda3/lib/python3.5/site-packages/flask/app.py", line 1988, in wsgi_app
    response = self.full_dispatch_request()
  File "/home/ubuntu/miniconda3/lib/python3.5/site-packages/flask/app.py", line 1639, in full_dispatch_request
    rv = self.dispatch_request()
  File "/home/ubuntu/miniconda3/lib/python3.5/site-packages/flask/app.py", line 1544, in handle_user_exception
    reraise(exc_type, exc_value, tb)
  File "/home/ubuntu/miniconda3/lib/python3.5/site-packages/flask/_compat.py", line 33, in reraise
    raise value
  File "/home/ubuntu/miniconda3/lib/python3.5/site-packages/flask/app.py", line 1639, in full_dispatch_request
    rv = self.dispatch_request()
  File "/home/ubuntu/miniconda3/lib/python3.5/site-packages/flask/app.py", line 1625, in dispatch_request
    return self.view_functions[rule.endpoint](**req.view_args)
  File "/home/ubuntu/workspace/finance/app/views.py", line 25, in equity_screener
    eqsc_post(request)
  File "/home/ubuntu/workspace/finance/app/equity_screener/equity_screener.py", line 14, in post
    get_data(reset_ticks=False)
  File "/home/ubuntu/workspace/finance/app/equity_screener/equity_screener.py", line 22, in get_data
    EquityStats.setColumns()
  File "/home/ubuntu/workspace/finance/app/equity_screener/equity_stats.py", line 36, in setColumns
    final_cols = ["Symbol"]
  File "/home/ubuntu/workspace/finance/app/equity_screener/equity_stats.py", line 36, in setColumns
    final_cols = ["Symbol"]
  File "/home/ubuntu/miniconda3/lib/python3.5/bdb.py", line 48, in trace_dispatch
    return self.dispatch_line(frame)
  File "/home/ubuntu/miniconda3/lib/python3.5/bdb.py", line 67, in dispatch_line
    if self.quitting: raise BdbQuit
bdb.BdbQuit
2016-10-17 13:42:37,605 INFO: finance hub startup [in /home/ubuntu/workspace/finance/app/__init__.py:49]
2016-10-17 13:46:18,830 ERROR: Exception on /equity_screener [POST] [in /home/ubuntu/miniconda3/lib/python3.5/site-packages/flask/app.py:1587]
Traceback (most recent call last):
  File "/home/ubuntu/miniconda3/lib/python3.5/site-packages/flask/app.py", line 1988, in wsgi_app
    response = self.full_dispatch_request()
  File "/home/ubuntu/miniconda3/lib/python3.5/site-packages/flask/app.py", line 1639, in full_dispatch_request
    rv = self.dispatch_request()
  File "/home/ubuntu/miniconda3/lib/python3.5/site-packages/flask/app.py", line 1544, in handle_user_exception
    reraise(exc_type, exc_value, tb)
  File "/home/ubuntu/miniconda3/lib/python3.5/site-packages/flask/_compat.py", line 33, in reraise
    raise value
  File "/home/ubuntu/miniconda3/lib/python3.5/site-packages/flask/app.py", line 1639, in full_dispatch_request
    rv = self.dispatch_request()
  File "/home/ubuntu/miniconda3/lib/python3.5/site-packages/flask/app.py", line 1625, in dispatch_request
    return self.view_functions[rule.endpoint](**req.view_args)
  File "/home/ubuntu/workspace/finance/app/views.py", line 25, in equity_screener
    eqsc_post(request)
  File "/home/ubuntu/workspace/finance/app/equity_screener/equity_screener.py", line 14, in post
    get_data(reset_ticks=False)
  File "/home/ubuntu/workspace/finance/app/equity_screener/equity_screener.py", line 22, in get_data
    EquityStats.setColumns()
  File "/home/ubuntu/workspace/finance/app/equity_screener/equity_stats.py", line 35, in setColumns
    EquityStats.cols = column_map
  File "/home/ubuntu/workspace/finance/app/equity_screener/equity_stats.py", line 35, in setColumns
    EquityStats.cols = column_map
  File "/home/ubuntu/miniconda3/lib/python3.5/bdb.py", line 48, in trace_dispatch
    return self.dispatch_line(frame)
  File "/home/ubuntu/miniconda3/lib/python3.5/bdb.py", line 66, in dispatch_line
    self.user_line(frame)
bdb.BdbQuit
2016-10-17 19:45:35,030 INFO: finance hub startup [in /home/ubuntu/workspace/finance/app/__init__.py:49]
2016-10-17 19:46:26,492 INFO: finance hub startup [in /home/ubuntu/workspace/finance/app/__init__.py:49]
2016-10-17 19:46:45,168 INFO: finance hub startup [in /home/ubuntu/workspace/finance/app/__init__.py:49]
2016-10-17 19:46:53,708 INFO: finance hub startup [in /home/ubuntu/workspace/finance/app/__init__.py:49]
2016-10-17 19:53:59,143 INFO: finance hub startup [in /home/ubuntu/workspace/finance/app/__init__.py:49]
2016-10-17 19:54:22,306 INFO: request to http://finance.yahoo.com/d/quotes.csv?s=FLWS+SRCE+FOXA+FOX+TWOU+DDD+MMM+SIXD+EGHT+AVHI&f=jp6wm6w1j5lc8e7cp1v7pd1j6k4mrdk5b4c6sm8k3p2l2g1j1vj3s7g4eb2r1bym2e9ng3p5k2t1l1g6f6s1m7e1har6or2i5t8m4e8r7l3d2g5xa2n4qb3b6w4k1c3t7kj4r5m5t6gc1v1ia5 successful [in equity_screener.py:50]
2016-10-17 19:55:08,768 INFO: finance hub startup [in /home/ubuntu/workspace/finance/app/__init__.py:49]
2016-10-17 19:55:29,169 INFO: request to http://finance.yahoo.com/d/quotes.csv?s=FLWS+SRCE+FOXA+FOX+TWOU+DDD+MMM+SIXD+EGHT+AVHI&f=d2m7pj6j5g3j4i5t8w1b6r2p5k2s7f6s1m8ob4c6dv1ye7p2d1lxr5l2wep6c3p1mr7g6sj1nj3m2c8k3k5t7bjrg1m6e1t1a5c1cl1k1r1l3m5t6n4k4g4v7e8g5ia2qr6ke9b3w4b2gvhm4a successful [in equity_screener.py:50]
